Workbook
Name DATE1: '[1]2019AP訂單6-9月'!$C:$C
Name 訂單來源: [1]目錄!$J$3:$J$17

Sheet 訂單系統
A1: 手 | B1: HC平台案件總案件數 | C1: 手 | D1: 2 | N1: 手 | O1: 程式自動 | P1: 手 | Q1: 程式自動 | R1: 程式自動 | S1: 程式自動 | T1: 程式自動 | U1: 程式自動 | V1: 程式自動 | W1: 手 | X1: 程式自動 | Y1: 程式自動 | Z1: 程式自動 | AA1: 手 | AB1: 手 | AC1: 程式自動 | AE1: 程式帶入 | AF1: 程式帶入 | AG1: 程式帶入 | AH1: 程式帶入 | AI1: 程式帶入 | AJ1: 手 | AK1: 手 | AL1: 手 | AM1: 程式帶入 | AN1: 程式帶入 | AO1: 程式帶入-週報用
A2: 備註 | B2: 主目錄 | C2: 訂單編號 | D2: 服務時段 | E2: 服務開始日 | F2: 客戶 | G2: 天數 | H2: 補助資格 | I2: 服務時數 | J2: 時數 | K2: 補助時數 | L2: 自費時數 | M2: 請款總日數 | N2: 樓層費用 | O2: 市府訂單號碼 | P2: 訂金日期-小艾 | Q2: 雇主單價 | R2: 訂金天數 | S2: 訂金金額 | T2: 第一期款入帳日-0 | U2: 第一期款天數 | V2: 第一期金額 | W2: 第二期款入帳日-1 | X2: 第二期款天數 | Y2: 第二期金額 | Z2: 雇主自費合計金額 | AA2: 成立-小艾 | AB2: 服務人員 | AC2: 服務人員單價 | AD2: 其他加價 | AE2: 薪資總額 | AF2: 次月付款 | AG2: 補助款 | AH2: 補助款次次月付款 | AI2: 市府請款1 | AJ2: 服務開始 | AK2: 服務結束 | AL2: 特殊休假 | AM2: 服務人員銀行代號 | AN2: 服務人員帳號 | AO2: 休假方式 | AP2: 預產期-BECLASS | AQ2: 雇主 | AR2: 服務時數
A3: 備註 | B3: 主目錄 | C3: 訂單編號 | D3: 服務時段 | E3: 服務開始日 | F3: 客戶 | G3: 天數 | H3: 補助資格 | I3: 服務時數 | J3: 時數 | K3: 補助時數 | L3: 自費時數 | M3: 請款總日數 | N3: 樓層費用 | O3: 市府訂單號碼 | P3: 訂金日期-小艾 | Q3: 雇主單價 | R3: 訂金天數 | S3: 訂金 | T3: 第一期款入帳日-1 | U3: 第一期款天數 | V3: 第1 | W3: 第二期款入帳日-2 | X3: 第二期款天數 | Y3: 第2 | Z3: 雇主自費合計金額 | AA3: 成立-小艾 | AB3: 服務人員 | AC3: 服務單價 | AD3: 其他加價 | AE3: 服務薪資 | AF3: 付款日-1 | AG3: 補助薪資 | AH3: 付款日-2 | AI3: 市府請款1 | AJ3: 服務開始 | AK3: 服務結束 | AL3: 特殊休假 | AM3: 服務人員銀行代號 | AN3: 服務人員帳號 | AO3: 休假方式 | AP3: 預產期 | AR3: 服務薪資金額
A4: 公會手填 | B4: 流水號 | C4: 政府編號(市府表單) | D4: 市府表單 | E4: 市府表單 | F4: 市府表單 | G4: 市府表單 | H4: 市府表單 | I4: 算服務時段的時數 | J4: 天數*服務時數 | K4: 一般市民",40, | L4: 時數-補助時數 | M4: 自費時數/服務時數 | N4: 公會手填 | O4: 市府表單(重複) | P4: 公會手填 | Q4: 一般市民",300, | R4: 一般市民",5, | S4: 訂金天數*雇主單價*服務時數 | T4: 如果訂單成立， 入帳日=服務開始日期 | U4: 請款總日數-訂金天數 >15 U=15 請款總日數-訂金天數 <0 U=0 其他條件 :請款總日數-訂金天數 | V4: 第一期款天數*服務時數 *雇主單價 | W4: 如果第二期款天數是0就是0，不是0則第一期款入帳日+15 | X4: 請款總日數-訂金天數-第一期款天數 | Y4: 第二期款天數*服務時數*雇主單價 | Z4: 訂金+第一期金額+第二期金額+樓層費用 | AA4: 連接帳務資料庫 (收到訂金後系統要自動標記訂單成立) | AB4: 連接資料庫(案件配對成功後系統需要自動標記該案件的服務人員) | AC4: 一般市民",300, | AD4: 樓層費用 | AE4: (自費時數*服務單價)+其他加價 | AF4: 服務結束日下個月15號 | AG4: 補助時數*服務單價 | AH4: 服務結束日下下個月15號 | AI4: 如果有補助資格， 服務結束日下個月5號 | AJ4: 公會手填 | AK4: 公會手填 | AL4: 備註 公會手填 (或服務人員表單有寫) | AM4: 服務人員表單 | AN4: 服務人員表單 | AO4: BECLASS(客戶要求的) | AP4: BECLASS | AQ4: 客戶 | AR4: 服務薪資+補助薪資
C5: 主鍵 | I5: D | J5: G*I | K5: "補助市民",120, | L5: J-K | M5: L/I | Q5: "補助市民",300, | R5: "補助市民",0, | S5: R*Q*I | T5: AA=訂單成立,AM | U5: IF(AA=訂單成立, IF(M-R>15,15,IF(M-R<0,0,M-R)),"") | V5: U*I*Q | W5: IF(X=0,"",T+15 | X5: M-R-U | Y5: X*I*Q | Z5: S+V+Y+N | AC5: "補助市民",350, | AD5: N | AE5: (L*AC)+AD | AF5: AN,MOUTH+1,DAY=15 | AG5: K*AC | AH5: AN,MOUTH+2,DAY=15 | AI5: AN,MOUTH+1,DAY=5 | AQ5: F | AR5: AE+AG
K6: "非市民",0, | Q6: "非市民",350, | R6: "非市民",5, | AC6: "非市民",320,

Sheet 給服務人員的訂單資訊-1
A2: 訂單號碼(市府表單) | B2: 服務人員(服務人員表單)
A3: 客戶名稱(市府表單)
A4: 1、服務日期: | B4: 開始日期(市府表單) | C4: 至 | D4: 結束日期(市府表單)
A5: 受託服務期間，每日自 | B5: 服務時段(市府表單) | E5: 服務方式(市府表單) | F5: 日數: | G5: 希望服務天數(市府表單)
A6: 服務地址: | B6: 地址(市府表單) | F6: 寶寶資訊(市府表單)
A7: 服務費用(補助請款) | E7: 說明
A8: 請領補助費用 | B8: 補助薪資(訂單系統) | C8: 付款日-2(訂單系統) | E8: 特殊假日(訂單系統)
A9: 服務費用(雇主自費) | E9: 備註(訂單系統)
A10: 應領金額 | B10: 服務薪資(訂單系統) | C10: 付款日-1(訂單系統)
A14: 總計 | B14: 總薪資(自己加)

Sheet 給服務人員的訂單資訊-2
A1: 雇主 | B1: 客戶名稱(市府表單) | C1: 電話 | D1: 客戶電話(市府表單) | F1: 訂單號碼(市府表單)
A2: 地址 | B2: 地址(市府表單)
A3: 相關問題 | E3: 雇主回覆
A4: 飲食習慣(含是否可接受中藥) | D4: BECLASS | J4: 服務期間食材需求(可以照現有食材酌量選購)
A5: 呈上題，若遇無法媒合到葷食服務人員時，請問餐食部分是否可以接受蛋奶素餐食？ | D5: BECLASS | J5: 中藥/食材 | K5: 肉品 | L5: 蔬菜
A6: 餐飲含酒比例： | D6: BECLASS | J6: 四物 | K6: 雞腿 | L6: 青菜
A7: 料理用油：(可接受種類)： | D7: BECLASS | J7: 四君 | K7: 雞胸 | L7: 紅蘿蔔
A8: 媽咪有無過敏體質： | D8: BECLASS | J8: 四神 | K8: 排骨 | L8: 薑
A9: 特殊照護時應注意事項： | D9: BECLASS | J9: 枸杞 | K9: 豬/牛肉絲 | L9: 香菇
A10: 餐點喜忌備註： | D10: BECLASS | J10: 紅棗 | K10: 絞肉 | L10: 其他菇類
A11: 現有烹煮工具 | D11: BECLASS | J11: 黃耆 | K11: 雞蛋 | L11: 豆製品
A12: 洗澡水準備： | D12: BECLASS | J12: 杜仲 | K12: 魚排
A13: 哺乳方式： | D13: BECLASS | J13: 大豐草(洗澡)
A14: 三節計費:甲方同意需另支付當日薪資1倍予乙方。 | D14: BECLASS | J14: 黑豆
A15: 特殊計費:胎數 | D15: BECLASS | J15: 紅豆
A16: 透天服務樓層方式(會加收樓層費) | D16: BECLASS | J16: 白木耳
A17: 提供服務人員轎車停車位 | D17: BECLASS | J17: 紫米
A18: 服務時間內是否有其他寶寶 | D18: BECLASS | J18: 桂圓肉
J19: 米酒
J20: 麻油

Sheet 客戶契約
A1: 新竹市月子照顧服務人員職業工會坐月子到府服務定型化契約書 | F1: 訂單編號((市府表單))
A2: ■月子服務□到府管家
A3: 補助資格說明： | B3: 本補助方案之生效，以新竹市政府核定之補助資格為準；凡未經核定或資格不符者，本方案不具法律約束力。
A4: 訂金匯款須知： | B4: 請於下單後 5 日內完成訂金匯款。逾期未入帳者，系統將自動取消該訂單及相關服務計畫，且不保留原定服務人員與時段。
A5: 雙方同意訂立條款如下:
A6: 第一章 契約基本事項
A7: 本契約於 | B7: TODAY() | C7: 經甲方攜回審閱五日(契約審閱期間至少為五日)
A8: 申請人甲方簽名: | B8: 客戶名稱(市府表單) | F8: (親簽)
A9: 預產期(市府表單) | B9: 為甲方預產期，服務時間為甲方出院回府後開始服務計算期滿為止。
A10: 服務平台派選服務人員: | C10: 服務人員(綁定好的服務人員) | E10: 服務 (以下簡稱受託人乙方)
A11: 第二章 平台責任與權利
A12: 1.平台責任
A13: 提供合法合規之照顧服務媒合與管理。"
A14: 建立服務品質監督機制，包括隨機抽查與定期評估。"
A15: 妥善保存並保護委託人及受照顧者之個人資料。"
A16: 服務期間提供服務人員意外責任險。"
A17: 2.平台權力
A18: 得因委託人或受照顧者違反契約而終止服務。"
A19: 得依政府規範調整服務內容與流程。"
A20: 第三章 委託人與受照顧者
A21: 委託人如未滿二十歲且未結婚，應得其法定代理人之同意，契約方生效。"
A22: 本服務以照顧新生兒及產婦為主，委託人不得任意增加受照顧人數；受照顧者如需增加，應另行收費。
A23: 本契約照顧新生兒:
A24: 一、委託日期_ | B24: 開始日期(市府表單) | C24: 至 | D24: 結束日期(市府表單) | E24: 服務總天數: | F24: 希望服務天數(市府表單)
A25: 二、費用單價: | B25: 雇主單價(訂單系統) | C25: 元 | E25: 服務總時數: | F25: 時數(市府表單)
A26: ★★★依實際服務日期調整 如遇委託人（雇主）提前或延後生產，致原服務人員無法如期提供服務時，本平台有權依實際情況更換服務人員，以確保服務得以持續進行。
A27: 款項 | B27: 時數 | C27: 匯款日期 | D27: （市民方案每日最高補助4小時每小時NT$300 *雙胞胎每小時NT$450）
A28: 市府補助 | B28: 補助時數(訂單系統) | C28: 待請領 | D28: 每日服務時數: | E28: 服務時段(市府表單)
A29: 三、自費服務時數及費用單價: | C29: 服務時薪費用: | D29: 服務單價(訂單系統)
A30: 天數: | B30: =F24 -> 希望服務天數(市府表單) | C30: 請款時數: | D30: =F25 -> 時數(市府表單) | E30: 費用合計: | F30: =B38 -> 雇主自費合計金額(訂單系統) | G30: 元整
A31: □其他 年節(農曆過年(初一、初二、初三)、端午節、中秋節 休假 | E31: 特殊假日: | F31: 特殊休假(訂單系統)
A32: 甲方於年節(農曆過年(初一、初二、初三)、端午節、中秋節)仍需服務者，甲方同意需另支付當日薪資1倍予乙方。
A33: 款項 | B33: 金額 | C33: 匯款日期 | D33: 市府市府登記案號: | E33: 政府編號(市府表單)
A34: 訂金 | B34: 訂金(訂單系統) | C34: 訂金日期(訂單系統) | D34: 雇主登記MAIL: | E34: Email(市府表單)
A35: 第一期款 | B35: 第一期款(訂單系統) | C35: 第一期款入帳日(訂單系統) | D35: 服務款項匯款帳號：(代收付)
A36: 第二期款 | B36: 第二期款(訂單系統) | C36: 第二期款入帳日(訂單系統) | D36: 還不確定要給哪個帳號，但要連接帳號資訊
A37: 樓層費用 | B37: 樓層費用(訂單系統) | C37: 訂金日期(訂單系統) | D37: 新竹市月子照顧服務人員職業工會
A38: 總計金額: | B38: 雇主自費合計金額(訂單系統) | D38: 應匯款項 (逾時未匯款者，乙方可暫停合約。)
A39: 服務天數: | B39: =IFERROR(VLOOKUP($F$1,'[1]2019AP訂單6-9月'!C:AI,10,0),"- ") -> - | C39: 補助款退款作業: 服務完成後,工會協助提出申請, 主管單位核發後轉入雇主帳戶 | D39: 每日服務時數: | E39: =E28 -> 服務時段(市府表單)
A40: 市府補助金額 | B40: 補助薪資(訂單系統) | D40: 雇主帳號: 銀行代號+分行代號(BECLASS) | E40: 銀行帳號(BECLASS)
...

Sheet 保險系統
A1: 要保單位名稱 | B1: 證號 | C1: 被保險人姓名 | D1: 職業等級 | E1: 加保日 | F1: 退保日 | J1: 要做出顯示誰需要加保誰需要退保的系統
A2: 新竹市月子照顧服務人員職業工會 | B2: 1 | D2: 1 | E2: 115/01/01
